Workbook

Sheet Raw_Data
A1: show_id | B1: type | C1: title | D1: director | E1: cast | F1: country | G1: date_added | H1: release_year | I1: rating | J1: duration | K1: listed_in | L1: description | M1: year_added | N1: IncludeRow
A2: s5 | B2: TV Show | C2: Kota Factory | E2: Mayur More, Jitendra Kumar, Ranjan Raj, Alam Khan, Ahsaas Channa, Revathi Pillai, Urvi Singh, Arun Kumar | F2: India | G2: 2021-09-24 | H2: 2021 | I2: TV-MA | J2: 2 Seasons | K2: International TV Shows, Romantic TV Shows, TV Comedies | L2: In a city of coaching centers known to train India’s finest collegiate minds, an earnest but unexceptional student and his friends navigate campus life. | M2: 2021 | N2: =IF(AND(OR(YearFilter="All",$M2=YearFilter),OR(RatingFilter="All",$I2=RatingFilter),OR(TypeFilter="All",$B2=TypeFilter),OR(GenreFilter="All",COUNTIFS(tblGenre[show_id],$A2,tblGenre[Genre],GenreFilter)>0)),1,0)
A3: s25 | B3: Movie | C3: Jeans | D3: S. Shankar | E3: Prashanth, Aishwarya Rai Bachchan, Sri Lakshmi, Nassar | F3: India | G3: 2021-09-21 | H3: 1998 | I3: TV-14 | J3: 166 min | K3: Comedies, International Movies, Romantic Movies | L3: When the father of the man she loves insists that his twin sons marry twin sisters, a woman creates an alter ego that might be a bit too convincing. | M3: 2021 | N3: =IF(AND(OR(YearFilter="All",$M3=YearFilter),OR(RatingFilter="All",$I3=RatingFilter),OR(TypeFilter="All",$B3=TypeFilter),OR(GenreFilter="All",COUNTIFS(tblGenre[show_id],$A3,tblGenre[Genre],GenreFilter)>0)),1,0)
A4: s30 | B4: Movie | C4: Paranoia | D4: Robert Luketic | E4: Liam Hemsworth, Gary Oldman, Amber Heard, Harrison Ford, Lucas Till, Embeth Davidtz, Julian McMahon, Josh Holloway, Richard Dreyfuss, Angela Sarafyan | F4: United States, India, France | G4: 2021-09-19 | H4: 2013 | I4: PG-13 | J4: 106 min | K4: Thrillers | L4: Blackmailed by his company's CEO, a low-level employee finds himself forced to spy on the boss's rival and former mentor. | M4: 2021 | N4: =IF(AND(OR(YearFilter="All",$M4=YearFilter),OR(RatingFilter="All",$I4=RatingFilter),OR(TypeFilter="All",$B4=TypeFilter),OR(GenreFilter="All",COUNTIFS(tblGenre[show_id],$A4,tblGenre[Genre],GenreFilter)>0)),1,0)
A5: s40 | B5: TV Show | C5: Chhota Bheem | E5: Vatsal Dubey, Julie Tejwani, Rupa Bhimani, Jigna Bhardwaj, Rajesh Kava, Mousam, Swapnil | F5: India | G5: 2021-09-16 | H5: 2021 | I5: TV-Y7 | J5: 3 Seasons | K5: Kids' TV | L5: A brave, energetic little boy with superhuman powers leads his friends on exciting adventures to guard their fellow Dholakpur villagers from evil. | M5: 2021 | N5: =IF(AND(OR(YearFilter="All",$M5=YearFilter),OR(RatingFilter="All",$I5=RatingFilter),OR(TypeFilter="All",$B5=TypeFilter),OR(GenreFilter="All",COUNTIFS(tblGenre[show_id],$A5,tblGenre[Genre],GenreFilter)>0)),1,0)
A6: s51 | B6: TV Show | C6: Dharmakshetra | E6: Kashmira Irani, Chandan Anand, Dinesh Mehta, Ankit Arora, Pushkar Goggiaa, Anjali Rana, Aarya DharmChand Kumar, Amit Behl, Maleeka Ghai | F6: India | G6: 2021-09-15 | H6: 2014 | I6: TV-PG | J6: 1 Season | K6: International TV Shows, TV Dramas, TV Sci-Fi & Fantasy | L6: After the ancient Great War, the god Chitragupta oversees a trial to determine who were the battle's true heroes and villains. | M6: 2021 | N6: =IF(AND(OR(YearFilter="All",$M6=YearFilter),OR(RatingFilter="All",$I6=RatingFilter),OR(TypeFilter="All",$B6=TypeFilter),OR(GenreFilter="All",COUNTIFS(tblGenre[show_id],$A6,tblGenre[Genre],GenreFilter)>0)),1,0)
A7: s67 | B7: TV Show | C7: Raja Rasoi Aur Anya Kahaniyan | F7: India | G7: 2021-09-15 | H7: 2014 | I7: TV-G | J7: 1 Season | K7: Docuseries, International TV Shows | L7: Explore the history and flavors of regional Indian cuisine, from traditional Kashmiri feasts to the vegetarian dishes of Gujarat. | M7: 2021 | N7: =IF(AND(OR(YearFilter="All",$M7=YearFilter),OR(RatingFilter="All",$I7=RatingFilter),OR(TypeFilter="All",$B7=TypeFilter),OR(GenreFilter="All",COUNTIFS(tblGenre[show_id],$A7,tblGenre[Genre],GenreFilter)>0)),1,0)
A8: s70 | B8: TV Show | C8: Stories by Rabindranath Tagore | F8: India | G8: 2021-09-15 | H8: 2015 | I8: TV-PG | J8: 1 Season | K8: International TV Shows, TV Dramas | L8: The writings of Nobel Prize winner Rabindranath Tagore come to life in this collection of tales set in early-20th-century Bengal. | M8: 2021 | N8: =IF(AND(OR(YearFilter="All",$M8=YearFilter),OR(RatingFilter="All",$I8=RatingFilter),OR(TypeFilter="All",$B8=TypeFilter),OR(GenreFilter="All",COUNTIFS(tblGenre[show_id],$A8,tblGenre[Genre],GenreFilter)>0)),1,0)
A9: s106 | B9: Movie | C9: Angamaly Diaries | D9: Lijo Jose Pellissery | E9: Antony Varghese, Reshma Rajan, Binny Rinky Benjamin, Vineeth Vishwam, Kichu Tellus, Sreekanth Dasan, Sarath Kumar, Tito Wilson, Anandhu, Bitto Davis, Sinoj Varghese | F9: India | G9: 2021-09-05 | H9: 2017 | I9: TV-14 | J9: 128 min | K9: Action & Adventure, Comedies, Dramas | L9: After growing up amidst the gang wars of his hometown, Vincent forms an entrepreneurial squad of his own and ends up on the wrong side of the law. | M9: 2021 | N9: =IF(AND(OR(YearFilter="All",$M9=YearFilter),OR(RatingFilter="All",$I9=RatingFilter),OR(TypeFilter="All",$B9=TypeFilter),OR(GenreFilter="All",COUNTIFS(tblGenre[show_id],$A9,tblGenre[Genre],GenreFilter)>0)),1,0)
A10: s115 | B10: Movie | C10: Anjaam | D10: Rahul Rawail | E10: Madhuri Dixit, Shah Rukh Khan, Tinnu Anand, Johny Lever, Kalpana Iyer, Himani Shivpuri, Sudha Chandran, Beena, Kiran Kumar | F10: India | G10: 2021-09-02 | H10: 1994 | I10: TV-14 | J10: 143 min | K10: Dramas, International Movies, Thrillers | L10: A wealthy industrialist’s dangerous obsession with a flight attendant destroys her world, until she takes matters into her own hands to exact revenge. | M10: 2021 | N10: =IF(AND(OR(YearFilter="All",$M10=YearFilter),OR(RatingFilter="All",$I10=RatingFilter),OR(TypeFilter="All",$B10=TypeFilter),OR(GenreFilter="All",COUNTIFS(tblGenre[show_id],$A10,tblGenre[Genre],GenreFilter)>0)),1,0)
A11: s117 | B11: Movie | C11: Dhanak | D11: Nagesh Kukunoor | E11: Krrish Chhabria, Hetal Gada, Vipin Sharma, Gulfam Khan, Suresh Menon, Vijay Maurya, Rajiv Lakshman, Ninad Kamat | F11: India | G11: 2021-09-02 | H11: 2015 | I11: TV-PG | J11: 114 min | K11: Comedies, Dramas, Independent Movies | L11: A movie-loving 10-year-old and her blind little brother trek to meet Indian superstar Shah Rukh Khan for help in getting the boy an eye operation. | M11: 2021 | N11: =IF(AND(OR(YearFilter="All",$M11=YearFilter),OR(RatingFilter="All",$I11=RatingFilter),OR(TypeFilter="All",$B11=TypeFilter),OR(GenreFilter="All",COUNTIFS(tblGenre[show_id],$A11,tblGenre[Genre],GenreFilter)>0)),1,0)
A12: s119 | B12: Movie | C12: Gurgaon | D12: Shanker Raman | E12: Akshay Oberoi, Pankaj Tripathi, Ragini Khanna, Aamir Bashir, Shalini Vatsa, Ashish Verma | F12: India | G12: 2021-09-02 | H12: 2017 | I12: TV-14 | J12: 106 min | K12: Dramas, International Movies, Thrillers | L12: When the daughter of a wealthy family returns from college, she gets a frosty welcome from her brother, who has problems – and plans – of his own. | M12: 2021 | N12: =IF(AND(OR(YearFilter="All",$M12=YearFilter),OR(RatingFilter="All",$I12=RatingFilter),OR(TypeFilter="All",$B12=TypeFilter),OR(GenreFilter="All",COUNTIFS(tblGenre[show_id],$A12,tblGenre[Genre],GenreFilter)>0)),1,0)
A13: s127 | B13: Movie | C13: Shikara | D13: Vidhu Vinod Chopra | E13: Aadil Khan, Sadia Khateeb, Zain Khan Durrani, Priyanshu Chatterjee, Bhavna Chauhan, Ashwin Dhar, Farid Azad Khan, Saghar Sehrai | F13: India | G13: 2021-09-02 | H13: 2020 | I13: TV-14 | J13: 115 min | K13: Dramas, International Movies, Romantic Movies | L13: A couple must strive to remain resilient after regional hostilities drive them from their beloved home into a refugee camp. | M13: 2021 | N13: =IF(AND(OR(YearFilter="All",$M13=YearFilter),OR(RatingFilter="All",$I13=RatingFilter),OR(TypeFilter="All",$B13=TypeFilter),OR(GenreFilter="All",COUNTIFS(tblGenre[show_id],$A13,tblGenre[Genre],GenreFilter)>0)),1,0)
A14: s191 | B14: Movie | C14: Thimmarusu | D14: Sharan Koppisetty | E14: Satya Dev, Priyanka Jawalkar, Brahmaji | F14: India | G14: 2021-08-28 | H14: 2021 | I14: TV-14 | J14: 125 min | K14: Dramas, International Movies | L14: Eight years after a young man is framed for murder, an up-and-coming lawyer re-opens the case, beginning a tricky mission to find the real culprit. | M14: 2021 | N14: =IF(AND(OR(YearFilter="All",$M14=YearFilter),OR(RatingFilter="All",$I14=RatingFilter),OR(TypeFilter="All",$B14=TypeFilter),OR(GenreFilter="All",COUNTIFS(tblGenre[show_id],$A14,tblGenre[Genre],GenreFilter)>0)),1,0)
A15: s193 | B15: Movie | C15: C Kkompany | D15: Sachin Yardi | E15: Mithun Chakraborty, Tusshar Kapoor, Anupam Kher, Rajpal Yadav, Raima Sen, Dilip Prabhavalkar, Sanjay Mishra | F15: India | G15: 2021-08-27 | H15: 2008 | I15: TV-14 | J15: 127 min | K15: Action & Adventure, Comedies, International Movies | L15: Three broke friends pose as an underworld gang for extortion, but their plan takes on a life of its own when their phony company becomes famous. | M15: 2021 | N15: =IF(AND(OR(YearFilter="All",$M15=YearFilter),OR(RatingFilter="All",$I15=RatingFilter),OR(TypeFilter="All",$B15=TypeFilter),OR(GenreFilter="All",COUNTIFS(tblGenre[show_id],$A15,tblGenre[Genre],GenreFilter)>0)),1,0)
A16: s196 | B16: Movie | C16: EMI: Liya Hai To Chukana Padega | D16: Saurabh Kabra | E16: Sanjay Dutt, Arjun Rampal, Malaika Arora, Aashish Chaudhary, Neha Uberoi, Urmila Matondkar, Manoj Joshi, Daya Shankar Pandey, Pushkar Jog, Kulbhushan Kharbanda | F16: India | G16: 2021-08-27 | H16: 2008 | I16: TV-14 | J16: 128 min | K16: Comedies, Dramas, International Movies | L16: A bank hires an enigmatic and unorthodox debt collector to recover money from four borrowers who are unable to pay their loans. | M16: 2021 | N16: =IF(AND(OR(YearFilter="All",$M16=YearFilter),OR(RatingFilter="All",$I16=RatingFilter),OR(TypeFilter="All",$B16=TypeFilter),OR(GenreFilter="All",COUNTIFS(tblGenre[show_id],$A16,tblGenre[Genre],GenreFilter)>0)),1,0)
A17: s200 | B17: Movie | C17: Koi Aap Sa | D17: Partho Mitra | E17: Aftab Shivdasani, Natassha, Dipannita Sharma, Himanshu Mallik, Vaidya Advai, Pushy Anand, Shama Deshpande, Rajendra Gupta | F17: India | G17: 2021-08-27 | H17: 2006 | I17: TV-14 | J17: 135 min | K17: Comedies, Dramas, International Movies | L17: Star athlete Rohan has his eye on a beautiful art student. But when his best friend Simran experiences a crisis, he drops everything to help her. | M17: 2021 | N17: =IF(AND(OR(YearFilter="All",$M17=YearFilter),OR(RatingFilter="All",$I17=RatingFilter),OR(TypeFilter="All",$B17=TypeFilter),OR(GenreFilter="All",COUNTIFS(tblGenre[show_id],$A17,tblGenre[Genre],GenreFilter)>0)),1,0)
A18: s201 | B18: Movie | C18: Krishna Cottage | D18: Santram Varma | E18: Sohail Khan, Isha Koppikar, Natassha, Rati Agnihotri, Vrajesh Hirjee, Divya Palat, Hiten Tejwani, Rajendranath Zutshi | F18: India | G18: 2021-08-27 | H18: 2004 | I18: TV-14 | J18: 124 min | K18: Action & Adventure, Horror Movies, International Movies | L18: True love is put to the test when another woman comes between a pair of star-crossed young lovers in this thriller. | M18: 2021 | N18: =IF(AND(OR(YearFilter="All",$M18=YearFilter),OR(RatingFilter="All",$I18=RatingFilter),OR(TypeFilter="All",$B18=TypeFilter),OR(GenreFilter="All",COUNTIFS(tblGenre[show_id],$A18,tblGenre[Genre],GenreFilter)>0)),1,0)
A19: s202 | B19: Movie | C19: Kucch To Hai | D19: Anil V. Kumar, Anurag Basu | E19: Tusshar Kapoor, Esha Deol, Natassha, Vrajesh Hirjee, Kusumit Sana, Rishi Kapoor, Moon Moon Sen, Johny Lever, Ashay Chitre, Jeetendra | F19: India | G19: 2021-08-27 | H19: 2003 | I19: TV-14 | J19: 136 min | K19: Dramas, International Movies, Thrillers | L19: A student tries to steal a test from a teacher's home, leaving him for dead after an accident. A string of murders may be the professor's revenge. | M19: 2021 | N19: =IF(AND(OR(YearFilter="All",$M19=YearFilter),OR(RatingFilter="All",$I19=RatingFilter),OR(TypeFilter="All",$B19=TypeFilter),OR(GenreFilter="All",COUNTIFS(tblGenre[show_id],$A19,tblGenre[Genre],GenreFilter)>0)),1,0)
A20: s203 | B20: Movie | C20: Kyaa Kool Hai Hum | D20: Sangeeth Sivan | E20: Tusshar Kapoor, Riteish Deshmukh, Isha Koppikar, Neha Dhupia, Anupam Kher, Jay Sean | F20: India | G20: 2021-08-27 | H20: 2005 | I20: TV-MA | J20: 165 min | K20: Comedies, International Movies, Music & Musicals | L20: Longtime friends Rahul and Karan head to Mumbai intent on making their dreams come true, but both men are suddenly saddled with bad luck. | M20: 2021 | N20: =IF(AND(OR(YearFilter="All",$M20=YearFilter),OR(RatingFilter="All",$I20=RatingFilter),OR(TypeFilter="All",$B20=TypeFilter),OR(GenreFilter="All",COUNTIFS(tblGenre[show_id],$A20,tblGenre[Genre],GenreFilter)>0)),1,0)
... A34: s260 | B34: Movie | C34: Pahuna | D34: Paakhi Tyrewala | E34: Anmol Limbu, Ishika Gurung, Manju Chettri, Banita Lagun, Binod Pradhan, Mahindra Bajgai, Rupa Tamang, Saran Rai | F34: India, Nepal | G34: 2021-08-18 | H34: 2018 | I34: TV-PG | J34: 82 min | K34: Comedies, Dramas, International Movies | L34: Fleeing unrest in their native Nepal, three young siblings separated from their parents must beat the odds to survive on their own in India. | M34: 2021 | N34: =IF(AND(OR(YearFilter="All",$M34=YearFilter),OR(RatingFilter="All",$I34=RatingFilter),OR(TypeFilter="All",$B34=TypeFilter),OR(GenreFilter="All",COUNTIFS(tblGenre[show_id],$A34,tblGenre[Genre],GenreFilter)>0)),1,0)
A35: s267 | B35: TV Show | C35: The Creative Indians | F35: India | G35: 2021-08-15 | H35: 2020 | I35: TV-MA | J35: 1 Season | K35: Docuseries, International TV Shows | L35: From chefs and comedians to filmmakers and fashion designers, India’s most notable imaginative minds share their artistic journeys. | M35: 2021 | N35: =IF(AND(OR(YearFilter="All",$M35=YearFilter),OR(RatingFilter="All",$I35=RatingFilter),OR(TypeFilter="All",$B35=TypeFilter),OR(GenreFilter="All",COUNTIFS(tblGenre[show_id],$A35,tblGenre[Genre],GenreFilter)>0)),1,0)
A36: s298 | B36: TV Show | C36: Navarasa | D36: Bejoy Nambiar, Priyadarshan, Karthik Narain, Vasanth Sai, Karthik Subbaraj, Arvind Swamy, Rathindran R Prasad, Sarjun, Gautham Vasudev Menon | E36: Suriya, Vijay Sethupathi, Revathy, Prakash Raj, Siddarth, Parvathy, Delhi Ganesh, Gautham Vasudev Menon, Anjali, Yogi Babu, Aditi Balan, Remya Nambeesan, Poorna, Prayaga Martin, Rythvika Suriya, Arvind Swamy, Prasanna, Atharva, Bobby Simha, Ashok Selvan, Nedumudi Venu, Kishore | F36: India | G36: 2021-08-06 | H36: 2021 | I36: TV-MA | J36: 1 Season | K36: TV Shows | L36: From amusement to awe, the nine human emotions of Indian aesthetic theory are explored in this anthology series. | M36: 2021 | N36: =IF(AND(OR(YearFilter="All",$M36=YearFilter),OR(RatingFilter="All",$I36=RatingFilter),OR(TypeFilter="All",$B36=TypeFilter),OR(GenreFilter="All",COUNTIFS(tblGenre[show_id],$A36,tblGenre[Genre],GenreFilter)>0)),1,0)
A37: s302 | B37: Movie | C37: Chennai Express | D37: Rohit Shetty | E37: Shah Rukh Khan, Deepika Padukone, Nikitin Dheer, Satyaraj, Kamini Kaushal, Lekh Tandon, Mukesh Tiwari | F37: India | G37: 2021-08-05 | H37: 2013 | I37: TV-14 | J37: 135 min | K37: Action & Adventure, Comedies, International Movies | L37: What could have been a sad journey turns joyful for Rahul when he falls in love with a woman en route to submerging his grandfather's ashes. | M37: 2021 | N37: =IF(AND(OR(YearFilter="All",$M37=YearFilter),OR(RatingFilter="All",$I37=RatingFilter),OR(TypeFilter="All",$B37=TypeFilter),OR(GenreFilter="All",COUNTIFS(tblGenre[show_id],$A37,tblGenre[Genre],GenreFilter)>0)),1,0)
A38: s384 | B38: Movie | C38: Department | D38: Ram Gopal Varma | E38: Amitabh Bachchan, Sanjay Dutt, Rana Daggubati, Vijay Raaz, Abhimanyu Singh, Madhu Shalini, Deepak Tijori, Anjana Sukhani, Manchu Lakshmi | F38: India | G38: 2021-07-27 | H38: 2012 | I38: TV-MA | J38: 143 min | K38: Action & Adventure, International Movies | L38: Two cops form a task force to take down two mobsters, but when a sinister politician enters the picture, dubious loyalties and motives come to light. | M38: 2021 | N38: =IF(AND(OR(YearFilter="All",$M38=YearFilter),OR(RatingFilter="All",$I38=RatingFilter),OR(TypeFilter="All",$B38=TypeFilter),OR(GenreFilter="All",COUNTIFS(tblGenre[show_id],$A38,tblGenre[Genre],GenreFilter)>0)),1,0)
A39: s411 | B39: Movie | C39: Chhota Bheem And The Broken Amulet | D39: Rajiv Chilaka | E39: Vatsal Dubey, Julie Tejwani, Rupa Bhimani, Jigna Bhardwaj, Rajesh Kava, Mousam, Swapnil | F39: India | G39: 2021-07-22 | H39: 2013 | I39: TV-Y7 | J39: 64 min | K39: Children & Family Movies | L39: When a stranger tries to steal an amulet from the palace, Bheem learns the sad story behind the ornament and heads to Africa to defeat the real villain. | M39: 2021 | N39: =IF(AND(OR(YearFilter="All",$M39=YearFilter),OR(RatingFilter="All",$I39=RatingFilter),OR(TypeFilter="All",$B39=TypeFilter),OR(GenreFilter="All",COUNTIFS(tblGenre[show_id],$A39,tblGenre[Genre],GenreFilter)>0)),1,0)
A40: s416 | B40: Movie | C40: Chhota Bheem aur Krishna | D40: Rajiv Chilaka | E40: Vatsal Dubey, Julie Tejwani, Rupa Bhimani, Jigna Bhardwaj, Rajesh Kava, Arun Shekher, Sanchit Wartak | F40: India | G40: 2021-07-22 | H40: 2009 | I40: TV-Y7 | J40: 68 min | K40: Children & Family Movies | L40: Centuries after the end of a conqueror's rule, he is mysteriously back from the dead. It’s up to Bheem to save Dholakpur from being taken over! | M40: 2021 | N40: =IF(AND(OR(YearFilter="All",$M40=YearFilter),OR(RatingFilter="All",$I40=RatingFilter),OR(TypeFilter="All",$B40=TypeFilter),OR(GenreFilter="All",COUNTIFS(tblGenre[show_id],$A40,tblGenre[Genre],GenreFilter)>0)),1,0)
A41: s519 | B41: Movie | C41: Har Kisse Ke Hisse: Kaamyaab | D41: Hardik Mehta | E41: Sanjay Mishra, Deepak Dobriyal, Sarika Singh, Isha Talwar, Avtar Gill, Kaurwakee Vashistha, Amitabh Srivastava, Vikas Verma | F41: India | G41: 2021-07-06 | H41: 2020 | I41: TV-14 | J41: 105 min | K41: Dramas, International Movies | L41: After a career of thankless credits, a retired actor returns for a long-awaited leading role but finds he is utterly unprepared for new-age filmmaking. | M41: 2021 | N41: =IF(AND(OR(YearFilter="All",$M41=YearFilter),OR(RatingFilter="All",$I41=RatingFilter),OR(TypeFilter="All",$B41=TypeFilter),OR(GenreFilter="All",COUNTIFS(tblGenre[show_id],$A41,tblGenre[Genre],GenreFilter)>0)),1,0)
A42: s529 | B42: Movie | C42: Rehmataan | D42: Rajveer Singh Maan, Harpeet Singh | E42: Guggu Gill, Sukhjinder Shera, Surinder Shinda, Deep Dhillon, Jasmine Jassi, Gurvinder Brar, Razia Sukhvir, Raj Virk | F42: India | G42: 2021-07-06 | H42: 2012 | I42: TV-14 | J42: 116 min | K42: Dramas, International Movies, Romantic Movies | L42: As unemployment, drug addiction and corruption plague a society, this drama depicts the people who believe there’s still good in the world. | M42: 2021 | N42: =IF(AND(OR(YearFilter="All",$M42=YearFilter),OR(RatingFilter="All",$I42=RatingFilter),OR(TypeFilter="All",$B42=TypeFilter),OR(GenreFilter="All",COUNTIFS(tblGenre[show_id],$A42,tblGenre[Genre],GenreFilter)>0)),1,0)
A43: s542 | B43: Movie | C43: Truckbhar Swapna | D43: Pramod Pawar | E43: Makrand Deshpande, Kranti Redkar, Mukesh Rishi, Manoj Joshi, Smita Tambe, Aaditi Pohankar, Sahil Gilbile, Jyoti Joshi | F43: India | G43: 2021-07-06 | H43: 2018 | I43: TV-14 | J43: 128 min | K43: Comedies, Dramas, International Movies | L43: A taxi driver living in a Mumbai slum seeks to better his family's life by building an extension of his home while dealing with a lecherous contractor. | M43: 2021 | N43: =IF(AND(OR(YearFilter="All",$M43=YearFilter),OR(RatingFilter="All",$I43=RatingFilter),OR(TypeFilter="All",$B43=TypeFilter),OR(GenreFilter="All",COUNTIFS(tblGenre[show_id],$A43,tblGenre[Genre],GenreFilter)>0)),1,0)
A44: s543 | B44: Movie | C44: Ujala | D44: Naresh Saigal | E44: Mala Sinha, Shammi Kapoor, Raaj Kumar, Leela Chitnis, Dhumal, Kumkum | F44: India | G44: 2021-07-06 | H44: 1959 | I44: TV-14 | J44: 143 min | K44: Dramas, International Movies | L44: An honest man dreams of a better life for his family, but a childhood friend leads him into a world of crime that keeps happiness just out of reach. | M44: 2021 | N44: =IF(AND(OR(YearFilter="All",$M44=YearFilter),OR(RatingFilter="All",$I44=RatingFilter),OR(TypeFilter="All",$B44=TypeFilter),OR(GenreFilter="All",COUNTIFS(tblGenre[show_id],$A44,tblGenre[Genre],GenreFilter)>0)),1,0)
A45: s552 | B45: Movie | C45: Haseen Dillruba | D45: Vinil Mathew | E45: Taapsee Pannu, Vikrant Massey, Harshvardhan Rane, Aditya Srivastava, Ashish Verma, Yamini Das, Daya Shankar Pandey | F45: India | G45: 2021-07-02 | H45: 2021 | I45: TV-MA | J45: 136 min | K45: International Movies, Romantic Movies, Thrillers | L45: Under investigation as a suspect in her husband’s murder, a wife reveals details of their thorny marriage that seem to only further blur the truth. | M45: 2021 | N45: =IF(AND(OR(YearFilter="All",$M45=YearFilter),OR(RatingFilter="All",$I45=RatingFilter),OR(TypeFilter="All",$B45=TypeFilter),OR(GenreFilter="All",COUNTIFS(tblGenre[show_id],$A45,tblGenre[Genre],GenreFilter)>0)),1,0)
A46: s736 | B46: Movie | C46: Sarbath | D46: Prabhakaran | E46: Kathir, Soori, Rahasya Gorak, Ashvatt | F46: India | G46: 2021-06-11 | H46: 2021 | I46: TV-PG | J46: 113 min | K46: Comedies, Dramas, International Movies | L46: When a city man returns to his native village for his brother’s wedding, several unforeseen snags make his visit more eventful than anticipated. | M46: 2021 | N46: =IF(AND(OR(YearFilter="All",$M46=YearFilter),OR(RatingFilter="All",$I46=RatingFilter),OR(TypeFilter="All",$B46=TypeFilter),OR(GenreFilter="All",COUNTIFS(tblGenre[show_id],$A46,tblGenre[Genre],GenreFilter)>0)),1,0)
A47: s737 | B47: Movie | C47: Skater Girl | D47: Manjari Makijany | E47: Rachel Saanchita Gupta, Amy Maghera, Shafin Patel, Ambrish Saxena, Swati Das, Jonathan Readwin, Ankit Yadav, Anurag Arora, Vinayak Gupta, Vivek Yadav, Waheeda Rehman | F47: United States, India | G47: 2021-06-11 | H47: 2021 | I47: PG | J47: 110 min | K47: Children & Family Movies, Dramas, International Movies | L47: When a teen in rural India discovers a life-changing passion for skateboarding, she faces a rough road as she follows her dream to compete. | M47: 2021 | N47: =IF(AND(OR(YearFilter="All",$M47=YearFilter),OR(RatingFilter="All",$I47=RatingFilter),OR(TypeFilter="All",$B47=TypeFilter),OR(GenreFilter="All",COUNTIFS(tblGenre[show_id],$A47,tblGenre[Genre],GenreFilter)>0)),1,0)
... A50: s874 | B50: Movie | C50: Ahaan | D50: Nikhil Pherwani | E50: Arif Zakaria, Abuli Mamaji, Niharika Singh, Rajit Kapoor, Plabita Borthakur, Shilpa Mehta, Kaizaad Kotwal, Sonali Sachdev, Haresh Raut | F50: India | G50: 2021-05-15 | H50: 2021 | I50: TV-MA | J50: 81 min | K50: Dramas, Independent Movies, International Movies | L50: Jilted by his wife, a man with OCD finds eye-opening common ground and camaraderie with his neighbor, a young man with Down Syndrome. | M50: 2021 | N50: =IF(AND(OR(YearFilter="All",$M50=YearFilter),OR(RatingFilter="All",$I50=RatingFilter),OR(TypeFilter="All",$B50=TypeFilter),OR(GenreFilter="All",COUNTIFS(tblGenre[show_id],$A50,tblGenre[Genre],GenreFilter)>0)),1,0)
A51: s877 | B51: TV Show | C51: Alma Matters | F51: India | G51: 2021-05-14 | H51: 2021 | I51: TV-MA | J51: 1 Season | K51: Docuseries, International TV Shows | L51: Alumni of India’s elite academic institutes share the harsh realities, pleasant surprises and transformative journeys of their college experiences. | M51: 2021 | N51: =IF(AND(OR(YearFilter="All",$M51=YearFilter),OR(RatingFilter="All",$I51=RatingFilter),OR(TypeFilter="All",$B51=TypeFilter),OR(GenreFilter="All",COUNTIFS(tblGenre[show_id],$A51,tblGenre[Genre],GenreFilter)>0)),1,0)
A52: s878 | B52: Movie | C52: Cinema Bandi | D52: Praveen Kandregula | E52: Vikas Vasistha, Sandeep Varanasi, Rag Mayur, Trishara, Munivenkatapa, Uma Yg, Sirivennela Yanamandhala, Sindhu Sreenivasa Murthy | F52: India | G52: 2021-05-14 | H52: 2021 | I52: TV-MA | J52: 99 min | K52: Comedies, Independent Movies, International Movies | L52: A struggling rickshaw driver’s life takes a rollicking turn when he comes upon an expensive camera and decides to make a film with his fellow villagers. | M52: 2021 | N52: =IF(AND(OR(YearFilter="All",$M52=YearFilter),OR(RatingFilter="All",$I52=RatingFilter),OR(TypeFilter="All",$B52=TypeFilter),OR(GenreFilter="All",COUNTIFS(tblGenre[show_id],$A52,tblGenre[Genre],GenreFilter)>0)),1,0)
A53: s893 | B53: Movie | C53: Tottaa Pataaka Item Maal | D53: Aditya Kripalani | E53: Shalini Vatsa, Chitrangada Chakraborty, Vinay Sharma, Sonal Joshi, Kritika Pande | F53: India | G53: 2021-05-13 | H53: 2018 | I53: TV-MA | J53: 107 min | K53: Dramas, Independent Movies, International Movies | L53: Exasperated with living in perpetual fear for their safety, four women kidnap a man to show him the realities of being female in Delhi. | M53: 2021 | N53: =IF(AND(OR(YearFilter="All",$M53=YearFilter),OR(RatingFilter="All",$I53=RatingFilter),OR(TypeFilter="All",$B53=TypeFilter),OR(GenreFilter="All",COUNTIFS(tblGenre[show_id],$A53,tblGenre[Genre],GenreFilter)>0)),1,0)
A54: s904 | B54: Movie | C54: Nayattu | D54: Martin Prakkat | E54: Kunchacko Boban, Joju George, Nimisha Sajayan, Jaffer Idukki, Yama Gilgamesh, Anil Nedumangad, Dineesh P, Vinod Sagar | F54: India | G54: 2021-05-09 | H54: 2021 | I54: TV-MA | J54: 122 min | K54: Dramas, International Movies, Thrillers | L54: Three police officers become pawns for unscrupulous lawmakers when they are framed in an incident amid political elections and must flee to evade arrest. | M54: 2021 | N54: =IF(AND(OR(YearFilter="All",$M54=YearFilter),OR(RatingFilter="All",$I54=RatingFilter),OR(TypeFilter="All",$B54=TypeFilter),OR(GenreFilter="All",COUNTIFS(tblGenre[show_id],$A54,tblGenre[Genre],GenreFilter)>0)),1,0)
A55: s910 | B55: Movie | C55: Milestone | D55: Ivan Ayr | E55: Suvinder Vicky, Lakshvir Saran, Mohinder Gujral, Gurinder Makna, Daljeet Singh, Akhilesh Kumar, Gaurika Bhatt, Arun Aseng | F55: India | G55: 2021-05-07 | H55: 2021 | I55: TV-14 | J55: 98 min | K55: Dramas, Independent Movies, International Movies | L55: Recently marking 500,000 kilometers on the road, a newly bereaved trucker faces the threat of losing the job that has come to define him to a new intern. | M55: 2021 | N55: =IF(AND(OR(YearFilter="All",$M55=YearFilter),OR(RatingFilter="All",$I55=RatingFilter),OR(TypeFilter="All",$B55=TypeFilter),OR(GenreFilter="All",COUNTIFS(tblGenre[show_id],$A55,tblGenre[Genre],GenreFilter)>0)),1,0)
...

Sheet Genre_Data
A1: show_id | B1: Genre | C1: Type_lookup | D1: Rating_lookup | E1: YearAdded_lookup | F1: IncludeRow_NoGenre
A2: s5 | B2: International TV Shows | C2: =IFERROR(INDEX(tblNetflix[type],MATCH($A2,tblNetflix[show_id],0)),"") | D2: =IFERROR(INDEX(tblNetflix[rating],MATCH($A2,tblNetflix[show_id],0)),"") | E2: =IFERROR(INDEX(tblNetflix[year_added],MATCH($A2,tblNetflix[show_id],0)),"") | F2: =IF(AND(OR(YearFilter="All",$E2=YearFilter),OR(RatingFilter="All",$D2=RatingFilter),OR(TypeFilter="All",$C2=TypeFilter)),1,0)
A3: s5 | B3: Romantic TV Shows | C3: =IFERROR(INDEX(tblNetflix[type],MATCH($A3,tblNetflix[show_id],0)),"") | D3: =IFERROR(INDEX(tblNetflix[rating],MATCH($A3,tblNetflix[show_id],0)),"") | E3: =IFERROR(INDEX(tblNetflix[year_added],MATCH($A3,tblNetflix[show_id],0)),"") | F3: =IF(AND(OR(YearFilter="All",$E3=YearFilter),OR(RatingFilter="All",$D3=RatingFilter),OR(TypeFilter="All",$C3=TypeFilter)),1,0)
A4: s5 | B4: TV Comedies | C4: =IFERROR(INDEX(tblNetflix[type],MATCH($A4,tblNetflix[show_id],0)),"") | D4: =IFERROR(INDEX(tblNetflix[rating],MATCH($A4,tblNetflix[show_id],0)),"") | E4: =IFERROR(INDEX(tblNetflix[year_added],MATCH($A4,tblNetflix[show_id],0)),"") | F4: =IF(AND(OR(YearFilter="All",$E4=YearFilter),OR(RatingFilter="All",$D4=RatingFilter),OR(TypeFilter="All",$C4=TypeFilter)),1,0)
A5: s25 | B5: Comedies | C5: =IFERROR(INDEX(tblNetflix[type],MATCH($A5,tblNetflix[show_id],0)),"") | D5: =IFERROR(INDEX(tblNetflix[rating],MATCH($A5,tblNetflix[show_id],0)),"") | E5: =IFERROR(INDEX(tblNetflix[year_added],MATCH($A5,tblNetflix[show_id],0)),"") | F5: =IF(AND(OR(YearFilter="All",$E5=YearFilter),OR(RatingFilter="All",$D5=RatingFilter),OR(TypeFilter="All",$C5=TypeFilter)),1,0)
A6: s25 | B6: International Movies | C6: =IFERROR(INDEX(tblNetflix[type],MATCH($A6,tblNetflix[show_id],0)),"") | D6: =IFERROR(INDEX(tblNetflix[rating],MATCH($A6,tblNetflix[show_id],0)),"") | E6: =IFERROR(INDEX(tblNetflix[year_added],MATCH($A6,tblNetflix[show_id],0)),"") | F6: =IF(AND(OR(YearFilter="All",$E6=YearFilter),OR(RatingFilter="All",$D6=RatingFilter),OR(TypeFilter="All",$C6=TypeFilter)),1,0)
A7: s25 | B7: Romantic Movies | C7: =IFERROR(INDEX(tblNetflix[type],MATCH($A7,tblNetflix[show_id],0)),"") | D7: =IFERROR(INDEX(tblNetflix[rating],MATCH($A7,tblNetflix[show_id],0)),"") | E7: =IFERROR(INDEX(tblNetflix[year_added],MATCH($A7,tblNetflix[show_id],0)),"") | F7: =IF(AND(OR(YearFilter="All",$E7=YearFilter),OR(RatingFilter="All",$D7=RatingFilter),OR(TypeFilter="All",$C7=TypeFilter)),1,0)
A8: s30 | B8: Thrillers | C8: =IFERROR(INDEX(tblNetflix[type],MATCH($A8,tblNetflix[show_id],0)),"") | D8: =IFERROR(INDEX(tblNetflix[rating],MATCH($A8,tblNetflix[show_id],0)),"") | E8: =IFERROR(INDEX(tblNetflix[year_added],MATCH($A8,tblNetflix[show_id],0)),"") | F8: =IF(AND(OR(YearFilter="All",$E8=YearFilter),OR(RatingFilter="All",$D8=RatingFilter),OR(TypeFilter="All",$C8=TypeFilter)),1,0)
A9: s40 | B9: Kids' TV | C9: =IFERROR(INDEX(tblNetflix[type],MATCH($A9,tblNetflix[show_id],0)),"") | D9: =IFERROR(INDEX(tblNetflix[rating],MATCH($A9,tblNetflix[show_id],0)),"") | E9: =IFERROR(INDEX(tblNetflix[year_added],MATCH($A9,tblNetflix[show_id],0)),"") | F9: =IF(AND(OR(YearFilter="All",$E9=YearFilter),OR(RatingFilter="All",$D9=RatingFilter),OR(TypeFilter="All",$C9=TypeFilter)),1,0)
A10: s51 | B10: International TV Shows | C10: =IFERROR(INDEX(tblNetflix[type],MATCH($A10,tblNetflix[show_id],0)),"") | D10: =IFERROR(INDEX(tblNetflix[rating],MATCH($A10,tblNetflix[show_id],0)),"") | E10: =IFERROR(INDEX(tblNetflix[year_added],MATCH($A10,tblNetflix[show_id],0)),"") | F10: =IF(AND(OR(YearFilter="All",$E10=YearFilter),OR(RatingFilter="All",$D10=RatingFilter),OR(TypeFilter="All",$C10=TypeFilter)),1,0)
A11: s51 | B11: TV Dramas | C11: =IFERROR(INDEX(tblNetflix[type],MATCH($A11,tblNetflix[show_id],0)),"") | D11: =IFERROR(INDEX(tblNetflix[rating],MATCH($A11,tblNetflix[show_id],0)),"") | E11: =IFERROR(INDEX(tblNetflix[year_added],MATCH($A11,tblNetflix[show_id],0)),"") | F11: =IF(AND(OR(YearFilter="All",$E11=YearFilter),OR(RatingFilter="All",$D11=RatingFilter),OR(TypeFilter="All",$C11=TypeFilter)),1,0)
A12: s51 | B12: TV Sci-Fi & Fantasy | C12: =IFERROR(INDEX(tblNetflix[type],MATCH($A12,tblNetflix[show_id],0)),"") | D12: =IFERROR(INDEX(tblNetflix[rating],MATCH($A12,tblNetflix[show_id],0)),"") | E12: =IFERROR(INDEX(tblNetflix[year_added],MATCH($A12,tblNetflix[show_id],0)),"") | F12: =IF(AND(OR(YearFilter="All",$E12=YearFilter),OR(RatingFilter="All",$D12=RatingFilter),OR(TypeFilter="All",$C12=TypeFilter)),1,0)
A13: s67 | B13: Docuseries | C13: =IFERROR(INDEX(tblNetflix[type],MATCH($A13,tblNetflix[show_id],0)),"") | D13: =IFERROR(INDEX(tblNetflix[rating],MATCH($A13,tblNetflix[show_id],0)),"") | E13: =IFERROR(INDEX(tblNetflix[year_added],MATCH($A13,tblNetflix[show_id],0)),"") | F13: =IF(AND(OR(YearFilter="All",$E13=YearFilter),OR(RatingFilter="All",$D13=RatingFilter),OR(TypeFilter="All",$C13=TypeFilter)),1,0)
... A2805: s8807 | B2805: Music & Musicals | C2805: =IFERROR(INDEX(tblNetflix[type],MATCH($A2805,tblNetflix[show_id],0)),"") | D2805: =IFERROR(INDEX(tblNetflix[rating],MATCH($A2805,tblNetflix[show_id],0)),"") | E2805: =IFERROR(INDEX(tblNetflix[year_added],MATCH($A2805,tblNetflix[show_id],0)),"") | F2805: =IF(AND(OR(YearFilter="All",$E2805=YearFilter),OR(RatingFilter="All",$D2805=RatingFilter),OR(TypeFilter="All",$C2805=TypeFilter)),1,0)

Sheet Theme_Data
A1: title | B1: description | C1: Theme | D1: Type_lookup | E1: Rating_lookup | F1: YearAdded_lookup | G1: IncludeRow
A2: Kota Factory | B2: In a city of coaching centers known to train India’s finest collegiate minds, an earnest but unexceptional student and his friends navigate campus life. | C2: Education & Youth | D2: =IFERROR(INDEX(tblNetflix[type],MATCH($A2,tblNetflix[title],0)),"") | E2: =IFERROR(INDEX(tblNetflix[rating],MATCH($A2,tblNetflix[title],0)),"") | F2: =IFERROR(INDEX(tblNetflix[year_added],MATCH($A2,tblNetflix[title],0)),"") | G2: =IF(AND(OR(YearFilter="All",$F2=YearFilter),OR(RatingFilter="All",$E2=RatingFilter),OR(TypeFilter="All",$D2=TypeFilter)),1,0)
A3: Jeans | B3: When the father of the man she loves insists that his twin sons marry twin sisters, a woman creates an alter ego that might be a bit too convincing. | C3: Romance | D3: =IFERROR(INDEX(tblNetflix[type],MATCH($A3,tblNetflix[title],0)),"") | E3: =IFERROR(INDEX(tblNetflix[rating],MATCH($A3,tblNetflix[title],0)),"") | F3: =IFERROR(INDEX(tblNetflix[year_added],MATCH($A3,tblNetflix[title],0)),"") | G3: =IF(AND(OR(YearFilter="All",$F3=YearFilter),OR(RatingFilter="All",$E3=RatingFilter),OR(TypeFilter="All",$D3=TypeFilter)),1,0)
A4: Paranoia | B4: Blackmailed by his company's CEO, a low-level employee finds himself forced to spy on the boss's rival and former mentor. | C4: Crime & Thriller | D4: =IFERROR(INDEX(tblNetflix[type],MATCH($A4,tblNetflix[title],0)),"") | E4: =IFERROR(INDEX(tblNetflix[rating],MATCH($A4,tblNetflix[title],0)),"") | F4: =IFERROR(INDEX(tblNetflix[year_added],MATCH($A4,tblNetflix[title],0)),"") | G4: =IF(AND(OR(YearFilter="All",$F4=YearFilter),OR(RatingFilter="All",$E4=RatingFilter),OR(TypeFilter="All",$D4=TypeFilter)),1,0)
A5: Chhota Bheem | B5: A brave, energetic little boy with superhuman powers leads his friends on exciting adventures to guard their fellow Dholakpur villagers from evil. | C5: Family & Children | D5: =IFERROR(INDEX(tblNetflix[type],MATCH($A5,tblNetflix[title],0)),"") | E5: =IFERROR(INDEX(tblNetflix[rating],MATCH($A5,tblNetflix[title],0)),"") | F5: =IFERROR(INDEX(tblNetflix[year_added],MATCH($A5,tblNetflix[title],0)),"") | G5: =IF(AND(OR(YearFilter="All",$F5=YearFilter),OR(RatingFilter="All",$E5=RatingFilter),OR(TypeFilter="All",$D5=TypeFilter)),1,0)
A6: Dharmakshetra | B6: After the ancient Great War, the god Chitragupta oversees a trial to determine who were the battle's true heroes and villains. | C6: Historical & Cultural | D6: =IFERROR(INDEX(tblNetflix[type],MATCH($A6,tblNetflix[title],0)),"") | E6: =IFERROR(INDEX(tblNetflix[rating],MATCH($A6,tblNetflix[title],0)),"") | F6: =IFERROR(INDEX(tblNetflix[year_added],MATCH($A6,tblNetflix[title],0)),"") | G6: =IF(AND(OR(YearFilter="All",$F6=YearFilter),OR(RatingFilter="All",$E6=RatingFilter),OR(TypeFilter="All",$D6=TypeFilter)),1,0)
A7: Raja Rasoi Aur Anya Kahaniyan | B7: Explore the history and flavors of regional Indian cuisine, from traditional Kashmiri feasts to the vegetarian dishes of Gujarat. | C7: Historical & Cultural | D7: =IFERROR(INDEX(tblNetflix[type],MATCH($A7,tblNetflix[title],0)),"") | E7: =IFERROR(INDEX(tblNetflix[rating],MATCH($A7,tblNetflix[title],0)),"") | F7: =IFERROR(INDEX(tblNetflix[year_added],MATCH($A7,tblNetflix[title],0)),"") | G7: =IF(AND(OR(YearFilter="All",$F7=YearFilter),OR(RatingFilter="All",$E7=RatingFilter),OR(TypeFilter="All",$D7=TypeFilter)),1,0)
A8: Stories by Rabindranath Tagore | B8: The writings of Nobel Prize winner Rabindranath Tagore come to life in this collection of tales set in early-20th-century Bengal. | C8: Historical & Cultural | D8: =IFERROR(INDEX(tblNetflix[type],MATCH($A8,tblNetflix[title],0)),"") | E8: =IFERROR(INDEX(tblNetflix[rating],MATCH($A8,tblNetflix[title],0)),"") | F8: =IFERROR(INDEX(tblNetflix[year_added],MATCH($A8,tblNetflix[title],0)),"") | G8: =IF(AND(OR(YearFilter="All",$F8=YearFilter),OR(RatingFilter="All",$E8=RatingFilter),OR(TypeFilter="All",$D8=TypeFilter)),1,0)
A9: Angamaly Diaries | B9: After growing up amidst the gang wars of his hometown, Vincent forms an entrepreneurial squad of his own and ends up on the wrong side of the law. | C9: Crime & Thriller | D9: =IFERROR(INDEX(tblNetflix[type],MATCH($A9,tblNetflix[title],0)),"") | E9: =IFERROR(INDEX(tblNetflix[rating],MATCH($A9,tblNetflix[title],0)),"") | F9: =IFERROR(INDEX(tblNetflix[year_added],MATCH($A9,tblNetflix[title],0)),"") | G9: =IF(AND(OR(YearFilter="All",$F9=YearFilter),OR(RatingFilter="All",$E9=RatingFilter),OR(TypeFilter="All",$D9=TypeFilter)),1,0)
A10: Anjaam | B10: A wealthy industrialist’s dangerous obsession with a flight attendant destroys her world, until she takes matters into her own hands to exact revenge. | C10: Crime & Thriller | D10: =IFERROR(INDEX(tblNetflix[type],MATCH($A10,tblNetflix[title],0)),"") | E10: =IFERROR(INDEX(tblNetflix[rating],MATCH($A10,tblNetflix[title],0)),"") | F10: =IFERROR(INDEX(tblNetflix[year_added],MATCH($A10,tblNetflix[title],0)),"") | G10: =IF(AND(OR(YearFilter="All",$F10=YearFilter),OR(RatingFilter="All",$E10=RatingFilter),OR(TypeFilter="All",$D10=TypeFilter)),1,0)
A11: Dhanak | B11: A movie-loving 10-year-old and her blind little brother trek to meet Indian superstar Shah Rukh Khan for help in getting the boy an eye operation. | C11: Family & Children | D11: =IFERROR(INDEX(tblNetflix[type],MATCH($A11,tblNetflix[title],0)),"") | E11: =IFERROR(INDEX(tblNetflix[rating],MATCH($A11,tblNetflix[title],0)),"") | F11: =IFERROR(INDEX(tblNetflix[year_added],MATCH($A11,tblNetflix[title],0)),"") | G11: =IF(AND(OR(YearFilter="All",$F11=YearFilter),OR(RatingFilter="All",$E11=RatingFilter),OR(TypeFilter="All",$D11=TypeFilter)),1,0)
A12: Gurgaon | B12: When the daughter of a wealthy family returns from college, she gets a frosty welcome from her brother, who has problems – and plans – of his own. | C12: Family & Children | D12: =IFERROR(INDEX(tblNetflix[type],MATCH($A12,tblNetflix[title],0)),"") | E12: =IFERROR(INDEX(tblNetflix[rating],MATCH($A12,tblNetflix[title],0)),"") | F12: =IFERROR(INDEX(tblNetflix[year_added],MATCH($A12,tblNetflix[title],0)),"") | G12: =IF(AND(OR(YearFilter="All",$F12=YearFilter),OR(RatingFilter="All",$E12=RatingFilter),OR(TypeFilter="All",$D12=TypeFilter)),1,0)
A13: Shikara | B13: A couple must strive to remain resilient after regional hostilities drive them from their beloved home into a refugee camp. | C13: Romance | D13: =IFERROR(INDEX(tblNetflix[type],MATCH($A13,tblNetflix[title],0)),"") | E13: =IFERROR(INDEX(tblNetflix[rating],MATCH($A13,tblNetflix[title],0)),"") | F13: =IFERROR(INDEX(tblNetflix[year_added],MATCH($A13,tblNetflix[title],0)),"") | G13: =IF(AND(OR(YearFilter="All",$F13=YearFilter),OR(RatingFilter="All",$E13=RatingFilter),OR(TypeFilter="All",$D13=TypeFilter)),1,0)
... A21: Kyaa Kool Hain Hum 3 | B21: When an unlikely porn actor falls for a woman outside the industry, he employs his co-stars as a stand-in traditional family to impress her father. | C21: Family & Children | D21: =IFERROR(INDEX(tblNetflix[type],MATCH($A21,tblNetflix[title],0)),"") | E21: =IFERROR(INDEX(tblNetflix[rating],MATCH($A21,tblNetflix[title],0)),"") | F21: =IFERROR(INDEX(tblNetflix[year_added],MATCH($A21,tblNetflix[title],0)),"") | G21: =IF(AND(OR(YearFilter="All",$F21=YearFilter),OR(RatingFilter="All",$E21=RatingFilter),OR(TypeFilter="All",$D21=TypeFilter)),1,0)

Sheet Pivot_Tables
A1: Total Titles | F1: Genre Distribution (Top 12)
A2: Metric | B2: Count | F2: Genre | G2: Titles
A3: Total Indian Titles | B3: =ROWS(tblNetflix) | F3: International Movies | G3: =COUNTIF(tblGenre[Genre],F3)
F4: Dramas | G4: =COUNTIF(tblGenre[Genre],F4)
A5: Movies vs TV Shows | F5: Comedies | G5: =COUNTIF(tblGenre[Genre],F5)
A6: Type | B6: Count | F6: Independent Movies | G6: =COUNTIF(tblGenre[Genre],F6)
A7: Movie | B7: =COUNTIF(tblNetflix[type],"Movie") | F7: Action & Adventure | G7: =COUNTIF(tblGenre[Genre],F7)
A8: TV Show | B8: =COUNTIF(tblNetflix[type],"TV Show") | F8: Romantic Movies | G8: =COUNTIF(tblGenre[Genre],F8)
F9: Music & Musicals | G9: =COUNTIF(tblGenre[Genre],F9)
A10: Year-wise Content Added | F10: Thrillers | G10: =COUNTIF(tblGenre[Genre],F10)
A11: Year | B11: Titles Added | F11: International TV Shows | G11: =COUNTIF(tblGenre[Genre],F11)
A12: 2016 | B12: =COUNTIF(tblNetflix[year_added],A12) | F12: Horror Movies | G12: =COUNTIF(tblGenre[Genre],F12)
A13: 2017 | B13: =COUNTIF(tblNetflix[year_added],A13) | F13: TV Dramas | G13: =COUNTIF(tblGenre[Genre],F13)
A14: 2018 | B14: =COUNTIF(tblNetflix[year_added],A14) | F14: Documentaries | G14: =COUNTIF(tblGenre[Genre],F14)
A15: 2019 | B15: =COUNTIF(tblNetflix[year_added],A15)
A16: 2020 | B16: =COUNTIF(tblNetflix[year_added],A16) | F16: Rating Distribution
A17: 2021 | B17: =COUNTIF(tblNetflix[year_added],A17) | F17: Rating | G17: Titles
F18: TV-14 | G18: =COUNTIF(tblNetflix[rating],F18)
A19: Top 10 Directors | F19: TV-MA | G19: =COUNTIF(tblNetflix[rating],F19)
A20: Director | B20: Titles | F20: TV-PG | G20: =COUNTIF(tblNetflix[rating],F20)
A21: David Dhawan | B21: =COUNTIF(tblNetflix[director],A21) | F21: TV-Y7 | G21: =COUNTIF(tblNetflix[rating],F21)
A22: Ram Gopal Varma | B22: =COUNTIF(tblNetflix[director],A22) | F22: PG-13 | G22: =COUNTIF(tblNetflix[rating],F22)
A23: Ashutosh Gowariker | B23: =COUNTIF(tblNetflix[director],A23) | F23: TV-G | G23: =COUNTIF(tblNetflix[rating],F23)
A24: Rajkumar Santoshi | B24: =COUNTIF(tblNetflix[director],A24) | F24: PG | G24: =COUNTIF(tblNetflix[rating],F24)
A25: Imtiaz Ali | B25: =COUNTIF(tblNetflix[director],A25) | F25: NR | G25: =COUNTIF(tblNetflix[rating],F25)
A26: Anees Bazmee | B26: =COUNTIF(tblNetflix[director],A26) | F26: TV-Y | G26: =COUNTIF(tblNetflix[rating],F26)
A27: Sooraj R. Barjatya | B27: =COUNTIF(tblNetflix[director],A27) | F27: R | G27: =COUNTIF(tblNetflix[rating],F27)
A28: Milan Luthria | B28: =COUNTIF(tblNetflix[director],A28) | F28: TV-Y7-FV | G28: =COUNTIF(tblNetflix[rating],F28)
A29: Rohit Shetty | B29: =COUNTIF(tblNetflix[director],A29)
A30: Prakash Jha | B30: =COUNTIF(tblNetflix[director],A30) | F30: AI Theme Distribution (Top 20 sample)
F31: Theme | G31: Titles
F32: Crime & Thriller | G32: =COUNTIF(tblTheme[Theme],F32)
F33: Family & Children | G33: =COUNTIF(tblTheme[Theme],F33)
F34: Romance | G34: =COUNTIF(tblTheme[Theme],F34)
F35: Historical & Cultural | G35: =COUNTIF(tblTheme[Theme],F35)
F36: Education & Youth | G36: =COUNTIF(tblTheme[Theme],F36)
F37: Other | G37: =COUNTIF(tblTheme[Theme],F37)
F38: Comedy | G38: =COUNTIF(tblTheme[Theme],F38)
F39: Note: theme tagging covers a 20-title AI-categorized sample, not the full catalogue.

Sheet Chart_Source
A1: TYPE | B1: Count | D1: YEAR | E1: Count | G1: DIRECTOR (COMEDIES) | H1: COMEDY TITLE COUNT | J1: GENRE | K1: Count | M1: RATING | N1: Count | P1: THEME | Q1: Count | S1: YearList | T1: GenreList | U1: RatingList | V1: TypeList
A2: Movie | B2: =SUMIFS(tblNetflix[IncludeRow],tblNetflix[type],A2) | D2: 2016 | E2: =SUMIFS(tblNetflix[IncludeRow],tblNetflix[year_added],D2) | G2: =LET(d,tblNetflix[director],inc,tblNetflix[IncludeRow],valid,(d<>"")*(inc=1),dirs,FILTER(d,valid,""),u,UNIQUE(dirs),c,MAP(u,LAMBDA(x,SUMIFS(tblNetflix[IncludeRow],tblNetflix[director],x))),data,FILTER(HSTACK(u,c),u<>""),TAKE(SORTBY(data,CHOOSECOLS(data,2),-1,CHOOSECOLS(data,1),1),10)) | J2: International Movies | K2: =SUMIFS(tblGenre[IncludeRow_NoGenre],tblGenre[Genre],J2) | M2: TV-14 | N2: =SUMIFS(tblNetflix[IncludeRow],tblNetflix[rating],M2) | P2: Crime & Thriller | Q2: =SUMIFS(tblTheme[IncludeRow],tblTheme[Theme],P2) | S2: All | T2: All | U2: All | V2: All
A3: TV Show | B3: =SUMIFS(tblNetflix[IncludeRow],tblNetflix[type],A3) | D3: 2017 | E3: =SUMIFS(tblNetflix[IncludeRow],tblNetflix[year_added],D3) | J3: Dramas | K3: =SUMIFS(tblGenre[IncludeRow_NoGenre],tblGenre[Genre],J3) | M3: TV-MA | N3: =SUMIFS(tblNetflix[IncludeRow],tblNetflix[rating],M3) | P3: Family & Children | Q3: =SUMIFS(tblTheme[IncludeRow],tblTheme[Theme],P3) | S3: 2016 | T3: International Movies | U3: TV-14 | V3: Movie
D4: 2018 | E4: =SUMIFS(tblNetflix[IncludeRow],tblNetflix[year_added],D4) | J4: Comedies | K4: =SUMIFS(tblGenre[IncludeRow_NoGenre],tblGenre[Genre],J4) | M4: TV-PG | N4: =SUMIFS(tblNetflix[IncludeRow],tblNetflix[rating],M4) | P4: Romance | Q4: =SUMIFS(tblTheme[IncludeRow],tblTheme[Theme],P4) | S4: 2017 | T4: Dramas | U4: TV-MA | V4: TV Show
D5: 2019 | E5: =SUMIFS(tblNetflix[IncludeRow],tblNetflix[year_added],D5) | J5: Independent Movies | K5: =SUMIFS(tblGenre[IncludeRow_NoGenre],tblGenre[Genre],J5) | M5: TV-Y7 | N5: =SUMIFS(tblNetflix[IncludeRow],tblNetflix[rating],M5) | P5: Historical & Cultural | Q5: =SUMIFS(tblTheme[IncludeRow],tblTheme[Theme],P5) | S5: 2018 | T5: Comedies | U5: TV-PG
D6: 2020 | E6: =SUMIFS(tblNetflix[IncludeRow],tblNetflix[year_added],D6) | J6: Action & Adventure | K6: =SUMIFS(tblGenre[IncludeRow_NoGenre],tblGenre[Genre],J6) | M6: PG-13 | N6: =SUMIFS(tblNetflix[IncludeRow],tblNetflix[rating],M6) | P6: Education & Youth | Q6: =SUMIFS(tblTheme[IncludeRow],tblTheme[Theme],P6) | S6: 2019 | T6: Independent Movies | U6: TV-Y7
D7: 2021 | E7: =SUMIFS(tblNetflix[IncludeRow],tblNetflix[year_added],D7) | J7: Romantic Movies | K7: =SUMIFS(tblGenre[IncludeRow_NoGenre],tblGenre[Genre],J7) | M7: TV-G | N7: =SUMIFS(tblNetflix[IncludeRow],tblNetflix[rating],M7) | P7: Other | Q7: =SUMIFS(tblTheme[IncludeRow],tblTheme[Theme],P7) | S7: 2020 | T7: Action & Adventure | U7: PG-13
J8: Music & Musicals | K8: =SUMIFS(tblGenre[IncludeRow_NoGenre],tblGenre[Genre],J8) | M8: PG | N8: =SUMIFS(tblNetflix[IncludeRow],tblNetflix[rating],M8) | P8: Comedy | Q8: =SUMIFS(tblTheme[IncludeRow],tblTheme[Theme],P8) | S8: 2021 | T8: Romantic Movies | U8: TV-G
J9: Thrillers | K9: =SUMIFS(tblGenre[IncludeRow_NoGenre],tblGenre[Genre],J9) | M9: NR | N9: =SUMIFS(tblNetflix[IncludeRow],tblNetflix[rating],M9) | T9: Music & Musicals | U9: PG
J10: International TV Shows | K10: =SUMIFS(tblGenre[IncludeRow_NoGenre],tblGenre[Genre],J10) | M10: TV-Y | N10: =SUMIFS(tblNetflix[IncludeRow],tblNetflix[rating],M10) | T10: Thrillers | U10: NR
J11: Horror Movies | K11: =SUMIFS(tblGenre[IncludeRow_NoGenre],tblGenre[Genre],J11) | M11: R | N11: =SUMIFS(tblNetflix[IncludeRow],tblNetflix[rating],M11) | T11: International TV Shows | U11: TV-Y
J12: TV Dramas | K12: =SUMIFS(tblGenre[IncludeRow_NoGenre],tblGenre[Genre],J12) | M12: TV-Y7-FV | N12: =SUMIFS(tblNetflix[IncludeRow],tblNetflix[rating],M12) | T12: Horror Movies | U12: R
G13: Top 10 Directors update automatically from the selected Genre + Year + Rating + Type filters. | J13: Documentaries | K13: =SUMIFS(tblGenre[IncludeRow_NoGenre],tblGenre[Genre],J13) | T13: TV Dramas | U13: TV-Y7-FV
T14: Documentaries
T15: TV Comedies
T16: Children & Family Movies
T17: Sports Movies
T18: Romantic TV Shows
T19: Kids' TV
T20: Sci-Fi & Fantasy
T21: Classic Movies
T22: Docuseries
T23: Crime TV Shows
T24: TV Horror
T25: Reality TV
... T37: Teen TV Shows

Sheet Dashboard
A1: NETFLIX INDIA CONTENT DEEP DIVE
A4: Interactive Microsoft Excel Dashboard | G4: ="Prepared: "&TEXT(TODAY(),"dd-mmm-yyyy")&" | Prepared By: Data Analytics Team"
A6: FILTERS
A7: Year | B7: All | D7: Genre | E7: All | G7: Rating | H7: All | J7: Type | K7: All
D8: Genre selector controls Top 10 Directors
A9: 🎬 | E9: 🎥 | I9: 📺
A11: =SUM(tblNetflix[IncludeRow]) | E11: =Chart_Source!$B$2 | I11: =Chart_Source!$B$3
A14: TOTAL INDIAN TITLES | E14: MOVIES | I14: TV SHOWS
A16: 🏷️ | E16: 🎭 | I16: ⭐
A18: =INDEX(Chart_Source!$J$2:$J$13,MATCH(MAX(Chart_Source!$K$2:$K$13),Chart_Source!$K$2:$K$13,0)) | E18: =INDEX(Chart_Source!$G$2:$G$11,MATCH(MAX(Chart_Source!$H$2:$H$11),Chart_Source!$H$2:$H$11,0)) | I18: =INDEX(Chart_Source!$M$2:$M$12,MATCH(MAX(Chart_Source!$N$2:$N$12),Chart_Source!$N$2:$N$12,0))
A21: TOP GENRE | E21: TOP DIRECTOR | I21: MOST COMMON RATING
G38: Top 10 Directors (Selected Genre)
A74: KEY INSIGHTS | G74: BUSINESS RECOMMENDATIONS
A75: • Movies dominate Indian Netflix content, outnumbering TV Shows roughly 11 to 1 (962 vs 84 titles). | G75: • Increase investment in regional-language and non-Hindi Indian content to diversify beyond the current catalogue mix.
A76: • International Movies is the single largest genre tag (864 tag-instances), ahead of Dramas (662) and Comedies (323). | G76: • Expand high-performing genres such as International Movies, Dramas and Comedies, which already drive the bulk of engagement.
A77: • Indian content additions accelerated sharply after 2017 -- titles added jumped from 162 in 2017 to a peak of 349 in 2018. | G77: • Develop more family-oriented and youth/education-themed titles to balance the current Crime & Thriller-heavy content skew.
A78: • TV-14 is the most common content rating (572 titles, ~55% of the catalogue), followed by TV-MA (266). | G78: • Strengthen long-term partnerships with consistently prolific directors to secure a steady content pipeline.
A79: • A small group of veteran Bollywood directors -- led by David Dhawan (9 titles) -- account for a disproportionate share of repeat contributions. | G79: • Prioritize TV-14 and TV-MA rated content, which together cover over 80% of the current library and the broadest addressable audience.
A80: • AI theme tagging on a 20-title sample shows Crime & Thriller and Family & Children as the most recurring narrative themes. | G80: • Continue scaling year-on-year content additions, building on the growth trajectory established since 2017.
